<?xml version="1.0"?>
<robot name="visual">
  <link name="motor">
    <visual>
      <geometry>
        <cylinder length="0.6" radius=".2"/>
      </geometry>
      <origin xyz="0 0 0"/>
      <material name="black">

      <color rgba=".1 .1 .1 1"/>
      </material>
    </visual>
  </link>

  <link name="base">
    <visual>
      <geometry>
        <box size="0.4 .1 .6"/>
      </geometry>
      <origin rpy="0 0 0" xyz="0 -0.15 0"/>
      <material name="white">
        <color rgba="1 1 1 1"/>
      </material>
    </visual>
  </link>

  <joint name="motor_to_base" type="fixed">
    <parent link="motor"/>
    <child link="base"/>
    <origin xyz="0 -0.15 0"/>
  </joint>


  <link name="left_finger">
    <visual>
      <geometry>
        <box size="0.1 .5 .1"/>
      </geometry>
      <origin rpy="0 0 -0.7" xyz="-0.4 -0.3 0"/>
      <material name="white">
        <color rgba="1 1 1 1"/>
      </material>
    </visual>
  </link>

  <joint name="base_to_left_finger" type="revolute">
    <axis xyz="0 0 1"/>
    <limit effort="1000.0" lower="0.0" upper="0.7" velocity="0.5"/>
    <parent link="base"/>
    <child link="left_finger"/>
    <origin xyz="-0.1 0 0"/>
  </joint>

  <link name="right_finger1">
    <visual>
      <geometry>
        <box size="0.1 .5 .1"/>
      </geometry>
      <origin rpy="0 0 0.7" xyz="0.4 -0.3 0.25"/>
      <material name="white">
        <color rgba="1 1 1 1"/>
      </material>
    </visual>
  </link>

  <joint name="base_to_right_finger1" type="revolute">
    <axis xyz="0 0 1"/>
    <limit effort="1000.0" lower="-0.7" upper="0.0" velocity="0.5"/>
    <parent link="base"/>
    <child link="right_finger1"/>
    <origin xyz=".1 0 0"/>
  </joint>

  <link name="right_finger2">
    <visual>
      <geometry>
        <box size="0.1 .5 .1"/>
      </geometry>
      <origin rpy="0 0 0.7" xyz="0.4 -0.3 -0.25"/>
      <material name="white">
        <color rgba="1 1 1 1"/>
      </material>
    </visual>
  </link>

  <joint name="base_to_right_finger2" type="revolute">
    <axis xyz="0 0 1"/>
    <limit effort="1000.0" lower="-0.7" upper="0.0" velocity="0.5"/>
    <parent link="base"/>
    <child link="right_finger2"/>
    <origin xyz=".1 0 0"/>
  </joint>

  <link name="left_fingertip">
    <visual>
      <geometry>
        <box size="0.1 .4 .1"/>
      </geometry>
      <origin rpy="0 0 0" xyz="0 -0.2 0"/>
      <material name="white">
        <color rgba="1 1 1 1"/>
      </material>
    </visual>
  </link>

  <joint name="left_finger_to_left_fingertip" type="revolute">
    <axis xyz="0 0 1"/>
    <limit effort="1.0" lower="0" upper="0.9" velocity="0.5"/>
    <parent link="left_finger"/>
    <child link="left_fingertip"/>
    <origin xyz="-0.6 -0.5 0"/>
  </joint>

  <link name="right_fingertip1">
    <visual>
      <geometry>
        <box size="0.1 .4 .1"/>
      </geometry>
      <origin rpy="0 0 0" xyz="0 -0.2 0"/>
      <material name="white">
        <color rgba="1 1 1 1"/>
      </material>
    </visual>
  </link>

  <joint name="right_finger1_to_right_fingertip1" type="revolute">
    <axis xyz="0 0 1"/>
    <limit effort="1.0" lower="-0.9" upper="0.0" velocity="0.5"/>
    <parent link="right_finger1"/>
    <child link="right_fingertip1"/>
    <origin xyz="0.6 -0.5 0.25"/>
  </joint>

  <link name="right_fingertip2">
    <visual>
      <geometry>
        <box size="0.1 .4 .1"/>
      </geometry>
      <origin rpy="0 0 0" xyz="0 -0.2 0"/>
      <material name="white">
        <color rgba="1 1 1 1"/>
      </material>
    </visual>
  </link>

  <joint name="right_finger2_to_right_fingertip2" type="revolute">
    <axis xyz="0 0 1"/>
    <limit effort="1.0" lower="-0.9" upper="0.0" velocity="0.5"/>
    <parent link="right_finger2"/>
    <child link="right_fingertip2"/>
    <origin xyz="0.6 -0.5 -0.25"/>
  </joint>

</robot>

